Started by upstream project "[8mha:////4Lkcno4r7vEEgNkkrfNKiDKUNH6BZ1b5wG8fNzjZ19zKAAAAnB+LCAAAAAAAAP9b85aBtbiIQTGjNKU4P08vOT+vOD8nVc83PyU1x6OyILUoJzMv2y+/JJUBAhiZGBgqihhk0NSjKDWzXb3RdlLBUSYGJk8GtpzUvPSSDB8G5tKinBIGIZ+sxLJE/ZzEvHT94JKizLx0a6BxUmjGOUNodHsLgAyuEgYB/az8JH3P3IL8opL44sIcfQDr6Y2rxQAAAA==[0mImport_sql" build number [8mha:////4LDpeNAcxmnRAW4p80pESwuI69isedrlyOxOHwivSgMmAAAAnB+LCAAAAAAAAP9b85aBtbiIQTGjNKU4P08vOT+vOD8nVc83PyU1x6OyILUoJzMv2y+/JJUBAhiZGBgqihhk0NSjKDWzXb3RdlLBUSYGJk8GtpzUvPSSDB8G5tKinBIGIZ+sxLJE/ZzEvHT94JKizLx0a6BxUmjGOUNodHsLQIwSBkH9rPwkfc/cgvyikvjiwhx9YwD2BR/rxgAAAA==[0m3
originally caused by:
 Started by upstream project "[8mha:////4PorWg8sno1ShOWtOE155KryydHFlHmu4KI9SPDStI8IAAAAoR+LCAAAAAAAAP9b85aBtbiIQTGjNKU4P08vOT+vOD8nVc83PyU1x6OyILUoJzMv2y+/JJUBAhiZGBgqihhk0NSjKDWzXb3RdlLBUSYGJk8GtpzUvPSSDB8G5tKinBIGIZ+sxLJE/ZzEvHT94JKizLx0a6BxUmjGOUNodHsLgAz+EgZR/az8JH3notTEktT4lMSSxKTE4lR9AN6u5q/KAAAA[0mCreate_database" build number [8mha:////4NUOCdaYuAy/+bULCdYptytes3hefPcyRGACc/DbU4TeAAAAoR+LCAAAAAAAAP9b85aBtbiIQTGjNKU4P08vOT+vOD8nVc83PyU1x6OyILUoJzMv2y+/JJUBAhiZGBgqihhk0NSjKDWzXb3RdlLBUSYGJk8GtpzUvPSSDB8G5tKinBIGIZ+sxLJE/ZzEvHT94JKizLx0a6BxUmjGOUNodHsLQIwSBjH9rPwkfeei1MSS1PiUxJLEpMTiVH1TAOP7Z/nLAAAA[0m5
 originally caused by:
  Started by user [8mha:////4IGVMtvk6iK1hwW+PI4nElqD5WuZBmgWM1foNK6n5D+9AAAAlx+LCAAAAAAAAP9b85aBtbiIQTGjNKU4P08vOT+vOD8nVc83PyU1x6OyILUoJzMv2y+/JJUBAhiZGBgqihhk0NSjKDWzXb3RdlLBUSYGJk8GtpzUvPSSDB8G5tKinBIGIZ+sxLJE/ZzEvHT94JKizLx0a6BxUmjGOUNodHsLgAzuEgZu/dLi1CL9ovyMzBIAOOgHy8AAAAA=[0mrohit gupta
Running as SYSTEM
Building in workspace /var/jenkins_home/workspace/diaspora_to_csv
[diaspora_to_csv] $ /bin/sh -xe /tmp/jenkins2813520345013327699.sh
+ python3 db_to_csv.py
/var/jenkins_home/workspace/diaspora_to_csv/db_to_csv.py:62: DeprecationWarning: This method will be removed in future versions.  Use 'parser.read_file()' instead.
  config.readfp(open('./tables.properties'))
/var/jenkins_home/workspace/diaspora_to_csv/db_to_csv.py:96: UserWarning: pandas only supports SQLAlchemy connectable (engine/connection) or database string URI or sqlite3 DBAPI2 connection. Other DBAPI2 objects are not tested. Please consider using SQLAlchemy.
  df = pd.read_sql("SELECT table_name FROM information_schema.tables WHERE table_schema = 'diaspora_v2'", mydb)
/var/jenkins_home/workspace/diaspora_to_csv/db_to_csv.py:127: UserWarning: pandas only supports SQLAlchemy connectable (engine/connection) or database string URI or sqlite3 DBAPI2 connection. Other DBAPI2 objects are not tested. Please consider using SQLAlchemy.
  results = pd.read_sql_query(query, mydb)
/var/jenkins_home/workspace/diaspora_to_csv/db_to_csv.py:160: FutureWarning: iteritems is deprecated and will be removed in a future version. Use .items instead.
  for h ,g in result[col].iteritems():
/var/jenkins_home/workspace/diaspora_to_csv/db_to_csv.py:127: UserWarning: pandas only supports SQLAlchemy connectable (engine/connection) or database string URI or sqlite3 DBAPI2 connection. Other DBAPI2 objects are not tested. Please consider using SQLAlchemy.
  results = pd.read_sql_query(query, mydb)
/var/jenkins_home/workspace/diaspora_to_csv/db_to_csv.py:127: UserWarning: pandas only supports SQLAlchemy connectable (engine/connection) or database string URI or sqlite3 DBAPI2 connection. Other DBAPI2 objects are not tested. Please consider using SQLAlchemy.
  results = pd.read_sql_query(query, mydb)
/var/jenkins_home/workspace/diaspora_to_csv/db_to_csv.py:127: UserWarning: pandas only supports SQLAlchemy connectable (engine/connection) or database string URI or sqlite3 DBAPI2 connection. Other DBAPI2 objects are not tested. Please consider using SQLAlchemy.
  results = pd.read_sql_query(query, mydb)
/var/jenkins_home/workspace/diaspora_to_csv/db_to_csv.py:127: UserWarning: pandas only supports SQLAlchemy connectable (engine/connection) or database string URI or sqlite3 DBAPI2 connection. Other DBAPI2 objects are not tested. Please consider using SQLAlchemy.
  results = pd.read_sql_query(query, mydb)
/var/jenkins_home/workspace/diaspora_to_csv/db_to_csv.py:127: UserWarning: pandas only supports SQLAlchemy connectable (engine/connection) or database string URI or sqlite3 DBAPI2 connection. Other DBAPI2 objects are not tested. Please consider using SQLAlchemy.
  results = pd.read_sql_query(query, mydb)
/var/jenkins_home/workspace/diaspora_to_csv/db_to_csv.py:127: UserWarning: pandas only supports SQLAlchemy connectable (engine/connection) or database string URI or sqlite3 DBAPI2 connection. Other DBAPI2 objects are not tested. Please consider using SQLAlchemy.
  results = pd.read_sql_query(query, mydb)
/var/jenkins_home/workspace/diaspora_to_csv/db_to_csv.py:127: UserWarning: pandas only supports SQLAlchemy connectable (engine/connection) or database string URI or sqlite3 DBAPI2 connection. Other DBAPI2 objects are not tested. Please consider using SQLAlchemy.
  results = pd.read_sql_query(query, mydb)
('diaspora_v3',)
select * from strains
[]
['140096']
['140096']
['140096', '160436']
select ID_projects, name, url, shortname, description, source_URL, logo, public, contact, timestamp from projects
select * from tolerance
select * from reference
select * from enzymes
select * from pigmentation
select * from sequence_genomes
select * from sequence_16s
Traceback (most recent call last):
  File "/usr/local/lib/python3.9/dist-packages/mysql/connector/connection_cext.py", line 608, in cmd_query
    self._cmysql.query(
_mysql_connector.MySQLInterfaceError: Table 'diaspora_v3.sequence_16s' doesn't exist

The above exception was the direct cause of the following exception:

Traceback (most recent call last):
  File "/usr/local/lib/python3.9/dist-packages/pandas/io/sql.py", line 2018, in execute
    cur.execute(*args, **kwargs)
  File "/usr/local/lib/python3.9/dist-packages/mysql/connector/cursor_cext.py", line 330, in execute
    result = self._cnx.cmd_query(
  File "/usr/local/lib/python3.9/dist-packages/mysql/connector/connection_cext.py", line 616, in cmd_query
    raise get_mysql_exception(
mysql.connector.errors.ProgrammingError: 1146 (42S02): Table 'diaspora_v3.sequence_16s' doesn't exist

The above exception was the direct cause of the following exception:

Traceback (most recent call last):
  File "/var/jenkins_home/workspace/diaspora_to_csv/db_to_csv.py", line 127, in <module>
    results = pd.read_sql_query(query, mydb)
  File "/usr/local/lib/python3.9/dist-packages/pandas/io/sql.py", line 397, in read_sql_query
    return pandas_sql.read_query(
  File "/usr/local/lib/python3.9/dist-packages/pandas/io/sql.py", line 2078, in read_query
    cursor = self.execute(*args)
  File "/usr/local/lib/python3.9/dist-packages/pandas/io/sql.py", line 2030, in execute
    raise ex from exc
pandas.errors.DatabaseError: Execution failed on sql 'select * from sequence_16s': 1146 (42S02): Table 'diaspora_v3.sequence_16s' doesn't exist
Build step 'Execute shell' marked build as failure
Finished: FAILURE
