Started by user [8mha:////4IGVMtvk6iK1hwW+PI4nElqD5WuZBmgWM1foNK6n5D+9AAAAlx+LCAAAAAAAAP9b85aBtbiIQTGjNKU4P08vOT+vOD8nVc83PyU1x6OyILUoJzMv2y+/JJUBAhiZGBgqihhk0NSjKDWzXb3RdlLBUSYGJk8GtpzUvPSSDB8G5tKinBIGIZ+sxLJE/ZzEvHT94JKizLx0a6BxUmjGOUNodHsLgAzuEgZu/dLi1CL9ovyMzBIAOOgHy8AAAAA=[0mrohit gupta
Running as SYSTEM
Building in workspace /var/jenkins_home/workspace/diaspora_to_csv
[diaspora_to_csv] $ /bin/sh -xe /tmp/jenkins11491611760124406978.sh
+ pip install pandas
Requirement already satisfied: pandas in /usr/local/lib/python3.9/dist-packages (1.4.3)
Requirement already satisfied: numpy>=1.18.5 in /usr/local/lib/python3.9/dist-packages (from pandas) (1.23.1)
Requirement already satisfied: python-dateutil>=2.8.1 in /usr/local/lib/python3.9/dist-packages (from pandas) (2.8.2)
Requirement already satisfied: pytz>=2020.1 in /usr/local/lib/python3.9/dist-packages (from pandas) (2022.1)
Requirement already satisfied: six>=1.5 in /usr/local/lib/python3.9/dist-packages (from python-dateutil>=2.8.1->pandas) (1.16.0)
WARNING: Running pip as the 'root' user can result in broken permissions and conflicting behaviour with the system package manager. It is recommended to use a virtual environment instead: https://pip.pypa.io/warnings/venv
+ python3 db_to_csv.py
/var/jenkins_home/workspace/diaspora_to_csv/db_to_csv.py:57: DeprecationWarning: This method will be removed in future versions.  Use 'parser.read_file()' instead.
  config.readfp(open('./tables.properties'))
Traceback (most recent call last):
  File "/var/jenkins_home/workspace/diaspora_to_csv/db_to_csv.py", line 78, in <module>
    mydb = pymysql.connect(
  File "/usr/local/lib/python3.9/dist-packages/pymysql/connections.py", line 353, in __init__
    self.connect()
  File "/usr/local/lib/python3.9/dist-packages/pymysql/connections.py", line 633, in connect
    self._request_authentication()
  File "/usr/local/lib/python3.9/dist-packages/pymysql/connections.py", line 932, in _request_authentication
    auth_packet = _auth.caching_sha2_password_auth(self, auth_packet)
  File "/usr/local/lib/python3.9/dist-packages/pymysql/_auth.py", line 265, in caching_sha2_password_auth
    data = sha2_rsa_encrypt(conn.password, conn.salt, conn.server_public_key)
  File "/usr/local/lib/python3.9/dist-packages/pymysql/_auth.py", line 143, in sha2_rsa_encrypt
    raise RuntimeError(
RuntimeError: 'cryptography' package is required for sha256_password or caching_sha2_password auth methods
Build step 'Execute shell' marked build as failure
Finished: FAILURE
