Started by user [8mha:////4IGVMtvk6iK1hwW+PI4nElqD5WuZBmgWM1foNK6n5D+9AAAAlx+LCAAAAAAAAP9b85aBtbiIQTGjNKU4P08vOT+vOD8nVc83PyU1x6OyILUoJzMv2y+/JJUBAhiZGBgqihhk0NSjKDWzXb3RdlLBUSYGJk8GtpzUvPSSDB8G5tKinBIGIZ+sxLJE/ZzEvHT94JKizLx0a6BxUmjGOUNodHsLgAzuEgZu/dLi1CL9ovyMzBIAOOgHy8AAAAA=[0mrohit gupta
Running as SYSTEM
Building in workspace /var/jenkins_home/workspace/diaspora_store_to_graph
[diaspora_store_to_graph] $ /bin/sh -xe /tmp/jenkins11493008070933334370.sh
+ pip3 install requests
Collecting requests
  Downloading requests-2.28.1-py3-none-any.whl (62 kB)
     ━━━━━━━━━━━━━━━━━━━━━━━━━━━━━━━━━━━━━━━━ 62.8/62.8 kB 4.7 MB/s eta 0:00:00
Collecting certifi>=2017.4.17
  Downloading certifi-2022.6.15-py3-none-any.whl (160 kB)
     ━━━━━━━━━━━━━━━━━━━━━━━━━━━━━━━━━━━━━━ 160.2/160.2 kB 11.0 MB/s eta 0:00:00
Collecting charset-normalizer<3,>=2
  Downloading charset_normalizer-2.1.0-py3-none-any.whl (39 kB)
Collecting urllib3<1.27,>=1.21.1
  Downloading urllib3-1.26.11-py2.py3-none-any.whl (139 kB)
     ━━━━━━━━━━━━━━━━━━━━━━━━━━━━━━━━━━━━━━ 139.9/139.9 kB 13.3 MB/s eta 0:00:00
Collecting idna<4,>=2.5
  Downloading idna-3.3-py3-none-any.whl (61 kB)
     ━━━━━━━━━━━━━━━━━━━━━━━━━━━━━━━━━━━━━━━━ 61.2/61.2 kB 7.3 MB/s eta 0:00:00
Installing collected packages: urllib3, idna, charset-normalizer, certifi, requests
Successfully installed certifi-2022.6.15 charset-normalizer-2.1.0 idna-3.3 requests-2.28.1 urllib3-1.26.11
WARNING: Running pip as the 'root' user can result in broken permissions and conflicting behaviour with the system package manager. It is recommended to use a virtual environment instead: https://pip.pypa.io/warnings/venv
+ python3 store.py
../diaspora_rdf_map/Mapping/output/cell_morphology.nt
Traceback (most recent call last):
  File "/usr/local/lib/python3.9/dist-packages/urllib3/connection.py", line 174, in _new_conn
    conn = connection.create_connection(
  File "/usr/local/lib/python3.9/dist-packages/urllib3/util/connection.py", line 95, in create_connection
    raise err
  File "/usr/local/lib/python3.9/dist-packages/urllib3/util/connection.py", line 85, in create_connection
    sock.connect(sa)
ConnectionRefusedError: [Errno 111] Connection refused

During handling of the above exception, another exception occurred:

Traceback (most recent call last):
  File "/usr/local/lib/python3.9/dist-packages/urllib3/connectionpool.py", line 703, in urlopen
    httplib_response = self._make_request(
  File "/usr/local/lib/python3.9/dist-packages/urllib3/connectionpool.py", line 398, in _make_request
    conn.request(method, url, **httplib_request_kw)
  File "/usr/local/lib/python3.9/dist-packages/urllib3/connection.py", line 239, in request
    super(HTTPConnection, self).request(method, url, body=body, headers=headers)
  File "/usr/lib/python3.9/http/client.py", line 1255, in request
    self._send_request(method, url, body, headers, encode_chunked)
  File "/usr/lib/python3.9/http/client.py", line 1301, in _send_request
    self.endheaders(body, encode_chunked=encode_chunked)
  File "/usr/lib/python3.9/http/client.py", line 1250, in endheaders
    self._send_output(message_body, encode_chunked=encode_chunked)
  File "/usr/lib/python3.9/http/client.py", line 1010, in _send_output
    self.send(msg)
  File "/usr/lib/python3.9/http/client.py", line 950, in send
    self.connect()
  File "/usr/local/lib/python3.9/dist-packages/urllib3/connection.py", line 205, in connect
    conn = self._new_conn()
  File "/usr/local/lib/python3.9/dist-packages/urllib3/connection.py", line 186, in _new_conn
    raise NewConnectionError(
urllib3.exceptions.NewConnectionError: <urllib3.connection.HTTPConnection object at 0x7f11826186a0>: Failed to establish a new connection: [Errno 111] Connection refused

During handling of the above exception, another exception occurred:

Traceback (most recent call last):
  File "/usr/local/lib/python3.9/dist-packages/requests/adapters.py", line 489, in send
    resp = conn.urlopen(
  File "/usr/local/lib/python3.9/dist-packages/urllib3/connectionpool.py", line 787, in urlopen
    retries = retries.increment(
  File "/usr/local/lib/python3.9/dist-packages/urllib3/util/retry.py", line 592, in increment
    raise MaxRetryError(_pool, url, error or ResponseError(cause))
urllib3.exceptions.MaxRetryError: HTTPConnectionPool(host='localhost', port=7200): Max retries exceeded with url: /repositories/Diaspora/statements (Caused by NewConnectionError('<urllib3.connection.HTTPConnection object at 0x7f11826186a0>: Failed to establish a new connection: [Errno 111] Connection refused'))

During handling of the above exception, another exception occurred:

Traceback (most recent call last):
  File "/var/jenkins_home/workspace/diaspora_store_to_graph/store.py", line 48, in <module>
    response = requests.post('http://localhost:7200/repositories/Diaspora/statements', data=rdf.encode('utf-8'), headers = headers)
  File "/usr/local/lib/python3.9/dist-packages/requests/api.py", line 115, in post
    return request("post", url, data=data, json=json, **kwargs)
  File "/usr/local/lib/python3.9/dist-packages/requests/api.py", line 59, in request
    return session.request(method=method, url=url, **kwargs)
  File "/usr/local/lib/python3.9/dist-packages/requests/sessions.py", line 587, in request
    resp = self.send(prep, **send_kwargs)
  File "/usr/local/lib/python3.9/dist-packages/requests/sessions.py", line 701, in send
    r = adapter.send(request, **kwargs)
  File "/usr/local/lib/python3.9/dist-packages/requests/adapters.py", line 565, in send
    raise ConnectionError(e, request=request)
requests.exceptions.ConnectionError: HTTPConnectionPool(host='localhost', port=7200): Max retries exceeded with url: /repositories/Diaspora/statements (Caused by NewConnectionError('<urllib3.connection.HTTPConnection object at 0x7f11826186a0>: Failed to establish a new connection: [Errno 111] Connection refused'))
Build step 'Execute shell' marked build as failure
Finished: FAILURE
